Workbook

Sheet Cover
B2: TEST REPORT DOCUMENT
A4: Project Name | B4: <Project Name> | E4: Creator
A5: Project Code | B5: <Project Code> | E5: Issue Date | F5: <Date when this test report is created>
A6: Document Code | B6: =B5&"_"&"XXX"&"_"&"vx.x" -> <Project Code>_XXX_vx.x | E6: Version
A9: Record of change
A10: Effective Date | B10: Version | C10: Change Item | D10: *A,D,M | E10: Change description | F10: Reference
A11: <Date when these changes are effective> | F11: <List of documents which are refered in this version.>

Sheet Test Cases
D1: TEST CASE LIST
B3: Wealthy Eater | D3: =#REF! -> #REF!
B4: SEP490 | D4: =#REF! -> #REF!
B5: Server: Node.js/Express, DB: MongoDB Atlas, Client: Flutter iOS/Android Emulator | D5: <List enviroment requires in this system 1. Server 2. Database 3. Web Browser ... >
B8: No | C8: Function Name | D8: Sheet Name | E8: Description | F8: Pre-Condition
C9: 1 | D9: [Backend] Auth | E9: Backend API
C10: 2 | D10: [Backend] Profile | E10: Backend API
C11: 3 | D11: [Backend] Recipes | E11: Backend API
C12: 4 | D12: [Backend] Meal Plans | E12: Backend API
C13: 5 | D13: [Backend] Consultations (Customer) | E13: Backend API
C14: 6 | D14: [Backend] Nutritionists Workspace | E14: Backend API
C15: 7 | D15: [Backend] Shopping List & Pantry | E15: Backend API
C16: 8 | D16: [Backend] Websocket & Chat | E16: Backend API
C17: 9 | D17: [Backend] Notifications & Webhooks | E17: Backend API
C18: 10 | D18: [Mobile] Authentication | E18: Mobile UI
C19: 11 | D19: [Mobile] Nutritionist Portal | E19: Mobile UI
C20: 12 | D20: [Mobile] Customer Dashboard | E20: Mobile UI
... C22: 14 | D22: [Mobile] Biometrics & Pantry | E22: Mobile UI

Sheet Test Statistics
B1: TEST STATISTICS
B3: Project Name | C3: <Project Name> | E3: Creator
B4: Project Code | C4: <Project Code> | E4: Reviewer/Approver
B5: Document Code | C5: =C4&"_"&"Test Report"&"_"&"vx.x" -> <Project Code>_Test Report_vx.x | E5: Issue Date | H5: <Date when this test report is created>
B6: Notes | C6: <List modules included in this release> ex: Release 1 includes 2 modules: Module1 and Module2
B10: No | C10: Module code | D10: Passed | E10: Failed | F10: Pending | G10: N/A | H10: Number of test cases
B11: 1 | C11: ='Backend API'!B2 | D11: ='Backend API'!B6 | E11: ='Backend API'!C6 | F11: ='Backend API'!D6 | G11: ='Backend API'!E6 | H11: ='Backend API'!B4
B12: 2 | C12: ='Mobile UI'!B2 | D12: ='Mobile UI'!B6 | E12: ='Mobile UI'!C6 | F12: ='Mobile UI'!D6 | G12: ='Mobile UI'!E6 | H12: ='Mobile UI'!B4
C14: Sub total | D14: =SUM(D9:D13) -> 0 | E14: =SUM(E9:E13) -> 0 | F14: =SUM(F9:F13) -> 11 | G14: =SUM(G9:G13) -> 0 | H14: =SUM(H9:H13) -> 15
C16: Test coverage | E16: =(D14+E14)*100/(H14-G14) -> 0 | F16: %
C17: Test successful coverage | E17: =D14*100/(H14-G14) -> 0 | F17: %

Sheet Backend API
A2: Feature | B2: Backend API System Test | R2: Passed
A3: Test requirement | B3: <Brief description about requirements which are tested in this sheet> | R3: Failed
A4: Number of TCs | B4: =COUNTA(B11:B1000) | R4: Pending
A5: Testing Round | B5: Passed | C5: Failed | D5: Pending | E5: N/A | R5: N/A
A6: Round 1 | B6: =COUNTIF($G10:$G998, B5) | C6: =COUNTIF($G10:$G998, C5) | D6: =COUNTIF($G10:$G998, D5) | E6: =COUNTIF($G10:$G998, E5)
A7: Round 2 | B7: =COUNTIF($J10:$J998, B5) | C7: =COUNTIF($J10:$J998, C5) | D7: =COUNTIF($J10:$J998, D5) | E7: =COUNTIF($J10:$J998, E5)
A8: Round 3 | B8: =COUNTIF($M10:$M998, B5) | C8: =COUNTIF($M10:$M998, C5) | D8: =COUNTIF($M10:$M998, D5) | E8: =COUNTIF($M10:$M998, E5)
A10: Test Case ID | B10: Test Case Description | C10: Test Case Procedure | D10: Expected Results | E10: Pre-conditions | F10: Round 1 | G10: Test date | H10: Tester | I10: Round 2 | J10: Test date | K10: Tester | L10: Round 3 | M10: Test date | N10: Tester | O10: Note
B11: Auth
B12: TC-001 | C12: POST /api/auth/login | D12: POST | E12: Total reqs: 27000, Avg: 110.31ms | F12: DB Running | G12: Passed
B13: TC-002 | C13: POST /api/auth/register | D13: POST | E13: Total reqs: 27000, Avg: 100.11ms | F13: DB Running | G13: Passed
B14: TC-003 | C14: POST /api/auth/verify-otp | D14: POST | E14: Total reqs: 27000, Avg: 98.60ms | F14: DB Running | G14: Passed
B15: TC-004 | C15: POST /api/auth/resend-otp | D15: POST | E15: Total reqs: 27000, Avg: 92.83ms | F15: DB Running | G15: Passed
B16: TC-005 | C16: POST /api/auth/refresh | D16: POST | E16: Total reqs: 27000, Avg: 93.02ms | F16: DB Running | G16: Passed
B17: TC-006 | C17: GET /api/auth/me | D17: GET | E17: Total reqs: 27000, Avg: 89.79ms | F17: DB Running | G17: Passed
B18: TC-007 | C18: POST /api/auth/google (OAuth) | D18: POST | E18: Total reqs: 27000, Avg: 104.75ms | F18: DB Running | G18: Passed
B19: TC-008 | C19: POST /api/auth/forget-password | D19: POST | E19: Total reqs: 27000, Avg: 91.52ms | F19: DB Running | G19: Passed
B20: TC-009 | C20: POST /api/auth/reset-password | D20: POST | E20: Total reqs: 27000, Avg: 92.01ms | F20: DB Running | G20: Passed
B21: Profile
B22: TC-010 | C22: GET /api/profile | D22: GET | E22: Total reqs: 27000, Avg: 90.41ms | F22: DB Running | G22: Passed
B23: TC-011 | C23: PUT /api/profile (biometrics) | D23: PUT | E23: Total reqs: 27000, Avg: 93.34ms | F23: DB Running | G23: Passed
B24: Recipes
B25: TC-012 | C25: GET /api/user/recipes | D25: GET | E25: Total reqs: 27000, Avg: 90.48ms | F25: DB Running | G25: Passed
B26: TC-013 | C26: GET /api/user/recipes/:id | D26: GET | E26: Total reqs: 27000, Avg: 179.88ms | F26: DB Running | G26: Passed
B27: TC-014 | C27: POST /api/user/recipes/:id/like | D27: POST | E27: Total reqs: 27000, Avg: 116.11ms | F27: DB Running | G27: Failed
B28: TC-015 | C28: GET /api/user/recipes/liked | D28: GET | E28: Total reqs: 27000, Avg: 89.81ms | F28: DB Running | G28: Passed
B29: TC-016 | C29: GET /api/user/recipes/liked/count | D29: GET | E29: Total reqs: 27000, Avg: 131.24ms | F29: DB Running | G29: Passed
B30: TC-017 | C30: POST /api/user/recipes/:id/reviews | D30: POST | E30: Total reqs: 27000, Avg: 94.94ms | F30: DB Running | G30: Passed
B31: TC-018 | C31: GET /api/user/recipes/:id/reviews | D31: GET | E31: Total reqs: 27000, Avg: 91.44ms | F31: DB Running | G31: Passed
B32: TC-019 | C32: GET /api/user/recipes/:id/reviews/mine | D32: GET | E32: Total reqs: 27000, Avg: 90.59ms | F32: DB Running | G32: Passed
B33: Meal Plans
B34: TC-020 | C34: GET /api/meal-plans/my-plan | D34: GET | E34: Total reqs: 27000, Avg: 92.00ms | F34: DB Running | G34: Passed
B35: TC-021 | C35: GET /api/meal-plans/daily-report | D35: GET | E35: Total reqs: 27000, Avg: 91.86ms | F35: DB Running | G35: Passed
B36: TC-022 | C36: GET /api/meal-plans/logs | D36: GET | E36: Total reqs: 27000, Avg: 91.58ms | F36: DB Running | G36: Passed
B37: TC-023 | C37: POST /api/meal-plans/items/:id/log | D37: POST | E37: Total reqs: 27000, Avg: 94.03ms | F37: DB Running | G37: Passed
B38: TC-024 | C38: PUT /api/meal-plans/logs/:id | D38: PUT | E38: Total reqs: 27000, Avg: 95.19ms | F38: DB Running | G38: Passed
B39: TC-025 | C39: POST /api/meal-plans/scan-meal | D39: POST | E39: Total reqs: 27000, Avg: 93.97ms | F39: DB Running | G39: Passed
B40: TC-026 | C40: POST /api/meal-plans/generate | D40: POST | E40: Total reqs: 27000, Avg: 210.90ms | F40: DB Running | G40: Passed
B41: Consultations (Customer)
B42: TC-027 | C42: POST /api/user/consultations/hire | D42: POST | E42: Total reqs: 27000, Avg: 111.35ms | F42: DB Running | G42: Passed
...

Sheet Mobile UI
A2: Feature | B2: Mobile E2E UI Test | R2: Passed
A3: Test requirement | B3: <Brief description about requirements which are tested in this sheet> | R3: Failed
A4: Number of TCs | B4: =COUNTA(B11:B1000) | R4: Pending
A5: Testing Round | B5: Passed | C5: Failed | D5: Pending | E5: N/A | R5: N/A
A6: Round 1 | B6: =COUNTIF($G10:$G998, B5) | C6: =COUNTIF($G10:$G998, C5) | D6: =COUNTIF($G10:$G998, D5) | E6: =COUNTIF($G10:$G998, E5)
A7: Round 2 | B7: =COUNTIF($J10:$J998, B5) | C7: =COUNTIF($J10:$J998, C5) | D7: =COUNTIF($J10:$J998, D5) | E7: =COUNTIF($J10:$J998, E5)
A8: Round 3 | B8: =COUNTIF($M10:$M998, B5) | C8: =COUNTIF($M10:$M998, C5) | D8: =COUNTIF($M10:$M998, D5) | E8: =COUNTIF($M10:$M998, E5)
A10: Test Case ID | B10: Test Case Description | C10: Test Case Procedure | D10: Expected Results | E10: Pre-conditions | F10: Round 1 | G10: Test date | H10: Tester | I10: Round 2 | J10: Test date | K10: Tester | L10: Round 3 | M10: Test date | N10: Tester | O10: Note
B11: Authentication
B12: TC-UI-001 | C12: Customer Login Invalid | D12: Enter wrong email/pass, tap Login | E12: Shows error | F12: App launched | G12: Passed
B13: TC-UI-002 | C13: Nav to Register | D13: Tap Register button | E13: Renders Register | F13: App launched | G13: Passed
B14: TC-UI-003 | C14: Nav to Forgot Password | D14: Tap Forgot Pass link | E14: Renders Forgot Pass | F14: App launched | G14: Passed
B15: Nutritionist Portal
B16: TC-UI-004 | C16: Nutritionist Dashboard | D16: Login as Nutritionist | E16: Renders Dashboard | F16: Valid nutritionist | G16: Failed
B17: Customer Dashboard
B18: TC-UI-005 | C18: Dashboard Nav | D18: Login as Customer, tap tabs | E18: Tabs switch without crash | F18: Valid customer | G18: Passed
B19: TC-UI-010 | C19: View Meal Plans | D19: Tap Plans tab | E19: Renders Meal Plans | F19: Valid customer | G19: Passed
B20: TC-UI-011 | C20: Nutritionists List | D20: Tap Nutritionists tab | E20: Renders List | F20: Valid customer | G20: Passed
B21: TC-UI-012 | C21: Notifications & Bot | D21: Tap Bell and Bot icons | E21: Renders overlays | F21: Valid customer | G21: Passed
B22: Recipes & Shopping
B23: TC-UI-006 | C23: Browse Recipes | D23: Navigate to Recipe sub-tabs | E23: Renders correctly | F23: Valid customer | G23: Passed
B24: TC-UI-009 | C24: View Shopping List | D24: Recipe > Shopping tab | E24: Renders Shopping List | F24: Valid customer | G24: Passed
B25: Biometrics & Pantry
B26: TC-UI-007 | C26: Edit Biometrics | D26: Profile > Biometrics | E26: Renders form | F26: Valid customer | G26: Passed
B27: TC-UI-008 | C27: Manage Pantry | D27: Home > Manage Pantry | E27: Renders Pantry | F27: Valid customer | G27: Passed
